<?xml version="1.0" ?>
<!-- =================================================================================== -->
<!-- |    This document was autogenerated by xacro from src/easyarm_description/urdf/easyarm_a1_h0617.urdf.xacro | -->
<!-- |    EDITING THIS FILE BY HAND IS NOT RECOMMENDED                                 | -->
<!-- =================================================================================== -->
<robot name="ass_easyarm_a1_h0617">
  <link name="base_link">
    <inertial>
      <origin rpy="0.0 0.0 0.0" xyz="1.85864301500435e-08 0.000170528015075361 0.0233752275370471"/>
      <mass value="0.141091157039369"/>
      <inertia ixx="0.000117337484347889" ixy="-9.04390040901409e-11" ixz="1.55362925573062e-11" iyy="0.0001185851036162" iyz="2.66614551541239e-07" izz="0.000208390027083898"/>
    </inertial>
    <visual>
      <origin rpy="0.0 0.0 0.0" xyz="0.0 0.0 0.0"/>
      <geometry>
        <mesh filename="package://easyarm_description/meshes/easyarm_h0616/base_link.STL"/>
      </geometry>
      <material name="">
        <color rgba="0.752941176470588 0.752941176470588 0.752941176470588 1.0"/>
      </material>
    </visual>
    <collision>
      <origin rpy="0.0 0.0 0.0" xyz="0.0 0.0 0.0"/>
      <geometry>
        <mesh filename="package://easyarm_description/meshes/easyarm_h0616/base_link.STL"/>
      </geometry>
    </collision>
  </link>
  <link name="Link1">
    <inertial>
      <origin rpy="0.0 0.0 0.0" xyz="1.8778e-10 -0.0029368 -0.023504"/>
      <mass value="0.14848"/>
      <inertia ixx="5.9195e-05" ixy="-5.7068e-09" ixz="7.3201e-13" iyy="5.8621e-05" iyz="-1.0137e-07" izz="6.0699e-05"/>
    </inertial>
    <visual>
      <origin rpy="0.0 0.0 0.0" xyz="0.0 0.0 0.0"/>
      <geometry>
        <mesh filename="package://easyarm_description/meshes/easyarm_h0616/Link1.STL"/>
      </geometry>
      <material name="">
        <color rgba="0.75294 0.75294 0.75294 1.0"/>
      </material>
    </visual>
    <collision>
      <origin rpy="0.0 0.0 0.0" xyz="0.0 0.0 0.0"/>
      <geometry>
        <mesh filename="package://easyarm_description/meshes/easyarm_h0616/Link1.STL"/>
      </geometry>
    </collision>
  </link>
  <joint name="Joint1" type="revolute">
    <origin rpy="3.1416 0.0 0.0" xyz="0.0 0.0 0.058"/>
    <parent link="base_link"/>
    <child link="Link1"/>
    <axis xyz="0.0 0.0 1.0"/>
    <limit effort="6.0" lower="-3.14" upper="3.14" velocity="10.0"/>
  </joint>
  <link name="Link2">
    <inertial>
      <origin rpy="0.0 0.0 0.0" xyz="1.9675e-13 0.14888357064008506 -0.023386015547895038"/>
      <mass value="0.7744593105296842"/>
      <inertia ixx="0.00013277" ixy="-1.1414e-08" ixz="1.3378e-19" iyy="0.00011937" iyz="2.5314e-16" izz="0.00013393"/>
    </inertial>
    <visual>
      <origin rpy="0.0 0.0 0.0" xyz="0.0 0.0 0.0"/>
      <geometry>
        <mesh filename="package://easyarm_description/meshes/easyarm_h0616/Link2.STL"/>
      </geometry>
      <material name="">
        <color rgba="0.75294 0.75294 0.75294 1.0"/>
      </material>
    </visual>
    <collision>
      <origin rpy="0.0 0.0 0.0" xyz="0.0 0.0 0.0"/>
      <geometry>
        <mesh filename="package://easyarm_description/meshes/easyarm_h0616/Link2.STL"/>
      </geometry>
    </collision>
  </link>
  <joint name="Joint2" type="revolute">
    <origin rpy="-1.5708 0.0 0.0" xyz="0.0 -0.045 -0.0214"/>
    <parent link="Link1"/>
    <child link="Link2"/>
    <axis xyz="0.0 0.0 1.0"/>
    <limit effort="6.0" lower="-3.14" upper="3.14" velocity="10.0"/>
  </joint>
  <link name="Link3">
    <inertial>
      <origin rpy="0.0 0.0 0.0" xyz="-1.93134327140323e-07 0.1716961962807577 0.03862004186243388"/>
      <mass value="0.5040220986569005"/>
      <inertia ixx="7.78611830449173e-05" ixy="5.64536059673564e-09" ixz="3.88896681156799e-10" iyy="6.63480692941198e-05" iyz="-2.53380690786543e-07" izz="7.791777594025e-05"/>
    </inertial>
    <visual>
      <origin rpy="0.0 0.0 0.0" xyz="0.0 0.0 0.0"/>
      <geometry>
        <mesh filename="package://easyarm_description/meshes/easyarm_h0616/Link3.STL"/>
      </geometry>
      <material name="">
        <color rgba="0.752941176470588 0.752941176470588 0.752941176470588 1.0"/>
      </material>
    </visual>
    <collision>
      <origin rpy="0.0 0.0 0.0" xyz="0.0 0.0 0.0"/>
      <geometry>
        <mesh filename="package://easyarm_description/meshes/easyarm_h0616/Link3.STL"/>
      </geometry>
    </collision>
  </link>
  <joint name="Joint3" type="revolute">
    <origin rpy="0.0 0.0 0.0" xyz="0.0 0.18 0.0"/>
    <parent link="Link2"/>
    <child link="Link3"/>
    <axis xyz="0.0 0.0 -1.0"/>
    <limit effort="6.0" lower="-3.14" upper="3.14" velocity="10.0"/>
  </joint>
  <link name="Link4">
    <inertial>
      <origin rpy="0.0 0.0 0.0" xyz="-2.9715e-10 -0.0256071706612383 0.04207217274784611"/>
      <mass value="0.38512475677337077"/>
      <inertia ixx="5.9195e-05" ixy="5.5776e-13" ixz="-5.7068e-09" iyy="6.0699e-05" iyz="1.0299e-07" izz="5.8621e-05"/>
    </inertial>
    <visual>
      <origin rpy="0.0 0.0 0.0" xyz="0.0 0.0 0.0"/>
      <geometry>
        <mesh filename="package://easyarm_description/meshes/easyarm_h0616/Link4.STL"/>
      </geometry>
      <material name="">
        <color rgba="0.75294 0.75294 0.75294 1.0"/>
      </material>
    </visual>
    <collision>
      <origin rpy="0.0 0.0 0.0" xyz="0.0 0.0 0.0"/>
      <geometry>
        <mesh filename="package://easyarm_description/meshes/easyarm_h0616/Link4.STL"/>
      </geometry>
    </collision>
  </link>
  <joint name="Joint4" type="revolute">
    <origin rpy="3.1416 0.0 0.0" xyz="0.0 0.172 0.0176"/>
    <parent link="Link3"/>
    <child link="Link4"/>
    <axis xyz="0.0 0.0 -1.0"/>
    <limit effort="6.0" lower="-3.14" upper="3.14" velocity="10.0"/>
  </joint>
  <link name="Link5">
    <inertial>
      <origin rpy="0.0 0.0 0.0" xyz="2.5974e-06 0.0104063809530744 0.0369714494779258"/>
      <mass value="0.06752108176639557"/>
      <inertia ixx="9.3201e-06" ixy="3.4243e-10" ixz="5.3817e-09" iyy="1.425e-05" iyz="-1.4514e-07" izz="9.8891e-06"/>
    </inertial>
    <visual>
      <origin rpy="0.0 0.0 0.0" xyz="0.0 0.0 0.0"/>
      <geometry>
        <mesh filename="package://easyarm_description/meshes/easyarm_h0616/Link5.STL"/>
      </geometry>
      <material name="">
        <color rgba="0.75294 0.75294 0.75294 1.0"/>
      </material>
    </visual>
    <collision>
      <origin rpy="0.0 0.0 0.0" xyz="0.0 0.0 0.0"/>
      <geometry>
        <mesh filename="package://easyarm_description/meshes/easyarm_h0616/Link5.STL"/>
      </geometry>
    </collision>
  </link>
  <joint name="Joint5" type="revolute">
    <origin rpy="1.5708 0.0 0.0" xyz="0.0 -0.0214 0.045"/>
    <parent link="Link4"/>
    <child link="Link5"/>
    <axis xyz="0.0 0.0 -1.0"/>
    <limit effort="6.0" lower="-3.14" upper="3.14" velocity="10.0"/>
  </joint>
  <link name="Link6">
    <inertial>
      <origin rpy="0.0 0.0 0.0" xyz="6.2237e-18 -0.0037014932714028725 -0.004262026896173586"/>
      <mass value="0.019926349172910973"/>
      <inertia ixx="2.6123e-06" ixy="-3.3894e-25" ixz="1.3422e-22" iyy="2.6123e-06" iyz="-2.6298e-22" izz="4.6702e-06"/>
    </inertial>
    <visual>
      <origin rpy="0.0 0.0 0.0" xyz="0.0 0.0 0.0"/>
      <geometry>
        <mesh filename="package://easyarm_description/meshes/easyarm_h0616/Link6.STL"/>
      </geometry>
      <material name="">
        <color rgba="0.75294 0.75294 0.75294 1.0"/>
      </material>
    </visual>
    <collision>
      <origin rpy="0.0 0.0 0.0" xyz="0.0 0.0 0.0"/>
      <geometry>
        <mesh filename="package://easyarm_description/meshes/easyarm_h0616/Link6.STL"/>
      </geometry>
    </collision>
  </link>
  <joint name="Joint6" type="revolute">
    <origin rpy="-1.5708 0.0 0.0" xyz="0.0 0.037 0.0399"/>
    <parent link="Link5"/>
    <child link="Link6"/>
    <axis xyz="0.0 0.0 -1.0"/>
    <limit effort="6.0" lower="-3.14" upper="3.14" velocity="10.0"/>
  </joint>
</robot>
